[2024-03-19T01:58:11.849+0000] {taskinstance.py:1979} INFO - Dependencies all met for dep_context=non-requeueable deps ti=<TaskInstance: source_to_gcs.Create_bigQuery_table manual__2024-03-19T01:47:33.877964+00:00 [queued]>
[2024-03-19T01:58:11.872+0000] {taskinstance.py:1979} INFO - Dependencies all met for dep_context=requeueable deps ti=<TaskInstance: source_to_gcs.Create_bigQuery_table manual__2024-03-19T01:47:33.877964+00:00 [queued]>
[2024-03-19T01:58:11.872+0000] {taskinstance.py:2193} INFO - Starting attempt 4 of 4
[2024-03-19T01:58:11.901+0000] {taskinstance.py:2217} INFO - Executing <Task(GCSToBigQueryOperator): Create_bigQuery_table> on 2024-03-19 01:47:33.877964+00:00
[2024-03-19T01:58:11.911+0000] {standard_task_runner.py:60} INFO - Started process 558 to run task
[2024-03-19T01:58:11.925+0000] {standard_task_runner.py:87} INFO - Running: ['***', 'tasks', 'run', 'source_to_gcs', 'Create_bigQuery_table', 'manual__2024-03-19T01:47:33.877964+00:00', '--job-id', '89', '--raw', '--subdir', 'DAGS_FOLDER/sourcetobucket.py', '--cfg-path', '/tmp/tmpdb4auhz8']
[2024-03-19T01:58:11.930+0000] {standard_task_runner.py:88} INFO - Job 89: Subtask Create_bigQuery_table
[2024-03-19T01:58:12.022+0000] {task_command.py:423} INFO - Running <TaskInstance: source_to_gcs.Create_bigQuery_table manual__2024-03-19T01:47:33.877964+00:00 [running]> on host 484fbc655ee6
[2024-03-19T01:58:12.210+0000] {taskinstance.py:2513} INFO - Exporting env vars: AIRFLOW_CTX_DAG_OWNER='***' AIRFLOW_CTX_DAG_ID='source_to_gcs' AIRFLOW_CTX_TASK_ID='Create_bigQuery_table' AIRFLOW_CTX_EXECUTION_DATE='2024-03-19T01:47:33.877964+00:00' AIRFLOW_CTX_TRY_NUMBER='4' AIRFLOW_CTX_DAG_RUN_ID='manual__2024-03-19T01:47:33.877964+00:00'
[2024-03-19T01:58:12.231+0000] {connection.py:269} WARNING - Connection schemes (type: google_cloud_platform) shall not contain '_' according to RFC3986.
[2024-03-19T01:58:12.235+0000] {base.py:83} INFO - Using connection ID 'gcp_***_conn' for task execution.
[2024-03-19T01:58:12.237+0000] {gcs_to_bigquery.py:379} INFO - Using existing BigQuery table for storing data...
[2024-03-19T01:58:12.359+0000] {taskinstance.py:2731} ERROR - Task failed with exception
Traceback (most recent call last):
  File "/home/airflow/.local/lib/python3.8/site-packages/airflow/models/taskinstance.py", line 444, in _execute_task
    result = _execute_callable(context=context, **execute_callable_kwargs)
  File "/home/airflow/.local/lib/python3.8/site-packages/airflow/models/taskinstance.py", line 414, in _execute_callable
    return execute_callable(context=context, **execute_callable_kwargs)
  File "/home/airflow/.local/lib/python3.8/site-packages/airflow/providers/google/cloud/transfers/gcs_to_bigquery.py", line 380, in execute
    self.configuration = self._use_existing_table()
  File "/home/airflow/.local/lib/python3.8/site-packages/airflow/providers/google/cloud/transfers/gcs_to_bigquery.py", line 580, in _use_existing_table
    destination_project_id, destination_dataset, destination_table = self.hook.split_tablename(
  File "/home/airflow/.local/lib/python3.8/site-packages/airflow/providers/google/cloud/hooks/bigquery.py", line 2281, in split_tablename
    raise ValueError(f"Expected table name in the format of <dataset>.<table>. Got: {table_input}")
ValueError: Expected table name in the format of <dataset>.<table>. Got: used_car_data_price
[2024-03-19T01:58:12.387+0000] {taskinstance.py:1149} INFO - Marking task as FAILED. dag_id=source_to_gcs, task_id=Create_bigQuery_table, execution_date=20240319T014733, start_date=20240319T015811, end_date=20240319T015812
[2024-03-19T01:58:12.431+0000] {standard_task_runner.py:107} ERROR - Failed to execute job 89 for task Create_bigQuery_table (Expected table name in the format of <dataset>.<table>. Got: used_car_data_price; 558)
[2024-03-19T01:58:12.547+0000] {local_task_job_runner.py:234} INFO - Task exited with return code 1
[2024-03-19T01:58:12.617+0000] {taskinstance.py:3312} INFO - 0 downstream tasks scheduled from follow-on schedule check
