[2024-03-19T01:57:08.940+0000] {taskinstance.py:1979} INFO - Dependencies all met for dep_context=non-requeueable deps ti=<TaskInstance: source_to_gcs.Create_bigQuery_table manual__2024-03-19T01:47:33.877964+00:00 [queued]>
[2024-03-19T01:57:08.957+0000] {taskinstance.py:1979} INFO - Dependencies all met for dep_context=requeueable deps ti=<TaskInstance: source_to_gcs.Create_bigQuery_table manual__2024-03-19T01:47:33.877964+00:00 [queued]>
[2024-03-19T01:57:08.958+0000] {taskinstance.py:2193} INFO - Starting attempt 3 of 3
[2024-03-19T01:57:08.981+0000] {taskinstance.py:2217} INFO - Executing <Task(GCSToBigQueryOperator): Create_bigQuery_table> on 2024-03-19 01:47:33.877964+00:00
[2024-03-19T01:57:08.991+0000] {standard_task_runner.py:60} INFO - Started process 537 to run task
[2024-03-19T01:57:08.998+0000] {standard_task_runner.py:87} INFO - Running: ['***', 'tasks', 'run', 'source_to_gcs', 'Create_bigQuery_table', 'manual__2024-03-19T01:47:33.877964+00:00', '--job-id', '88', '--raw', '--subdir', 'DAGS_FOLDER/sourcetobucket.py', '--cfg-path', '/tmp/tmpfyr9p9ie']
[2024-03-19T01:57:09.003+0000] {standard_task_runner.py:88} INFO - Job 88: Subtask Create_bigQuery_table
[2024-03-19T01:57:09.070+0000] {task_command.py:423} INFO - Running <TaskInstance: source_to_gcs.Create_bigQuery_table manual__2024-03-19T01:47:33.877964+00:00 [running]> on host 484fbc655ee6
[2024-03-19T01:57:09.183+0000] {taskinstance.py:2513} INFO - Exporting env vars: AIRFLOW_CTX_DAG_OWNER='***' AIRFLOW_CTX_DAG_ID='source_to_gcs' AIRFLOW_CTX_TASK_ID='Create_bigQuery_table' AIRFLOW_CTX_EXECUTION_DATE='2024-03-19T01:47:33.877964+00:00' AIRFLOW_CTX_TRY_NUMBER='3' AIRFLOW_CTX_DAG_RUN_ID='manual__2024-03-19T01:47:33.877964+00:00'
[2024-03-19T01:57:09.200+0000] {connection.py:269} WARNING - Connection schemes (type: google_cloud_platform) shall not contain '_' according to RFC3986.
[2024-03-19T01:57:09.202+0000] {base.py:83} INFO - Using connection ID 'gcp_***_conn' for task execution.
[2024-03-19T01:57:09.204+0000] {gcs_to_bigquery.py:379} INFO - Using existing BigQuery table for storing data...
[2024-03-19T01:57:09.261+0000] {bigquery.py:2328} INFO - Project is not included in destination_project_dataset_table: used_car_data_price.car_sales; using project "used-car-analysis"
[2024-03-19T01:57:09.262+0000] {gcs_to_bigquery.py:383} INFO - Executing: {'load': {'autodetect': True, 'createDisposition': 'CREATE_IF_NEEDED', 'destinationTable': {'projectId': 'used-car-analysis', 'datasetId': 'used_car_data_price', 'tableId': 'car_sales'}, 'sourceFormat': 'CSV', 'sourceUris': ['gs://used-car-price-analysis/gs://used-car-price-analysis/data/raw/car_sales.csv'], 'writeDisposition': 'WRITE_EMPTY', 'ignoreUnknownValues': False, 'skipLeadingRows': None, 'fieldDelimiter': ',', 'quote': None, 'allowQuotedNewlines': False, 'encoding': 'UTF-8'}}
[2024-03-19T01:57:09.264+0000] {bigquery.py:1613} INFO - Inserting job ***_source_to_gcs_Create_bigQuery_table_2024_03_19T01_47_33_877964_00_00_2ded59f6d8ec59650329bab56574cfa5
[2024-03-19T01:57:09.517+0000] {taskinstance.py:2731} ERROR - Task failed with exception
Traceback (most recent call last):
  File "/home/airflow/.local/lib/python3.8/site-packages/airflow/models/taskinstance.py", line 444, in _execute_task
    result = _execute_callable(context=context, **execute_callable_kwargs)
  File "/home/airflow/.local/lib/python3.8/site-packages/airflow/models/taskinstance.py", line 414, in _execute_callable
    return execute_callable(context=context, **execute_callable_kwargs)
  File "/home/airflow/.local/lib/python3.8/site-packages/airflow/providers/google/cloud/transfers/gcs_to_bigquery.py", line 384, in execute
    job: BigQueryJob | UnknownJob = self._submit_job(self.hook, job_id)
  File "/home/airflow/.local/lib/python3.8/site-packages/airflow/providers/google/cloud/transfers/gcs_to_bigquery.py", line 306, in _submit_job
    return hook.insert_job(
  File "/home/airflow/.local/lib/python3.8/site-packages/airflow/providers/google/common/hooks/base_google.py", line 485, in inner_wrapper
    return func(self, *args, **kwargs)
  File "/home/airflow/.local/lib/python3.8/site-packages/airflow/providers/google/cloud/hooks/bigquery.py", line 1616, in insert_job
    job_api_repr._begin()
  File "/home/airflow/.local/lib/python3.8/site-packages/google/cloud/bigquery/job/base.py", line 740, in _begin
    api_response = client._call_api(
  File "/home/airflow/.local/lib/python3.8/site-packages/google/cloud/bigquery/client.py", line 831, in _call_api
    return call()
  File "/home/airflow/.local/lib/python3.8/site-packages/google/api_core/retry/retry_unary.py", line 293, in retry_wrapped_func
    return retry_target(
  File "/home/airflow/.local/lib/python3.8/site-packages/google/api_core/retry/retry_unary.py", line 153, in retry_target
    _retry_error_helper(
  File "/home/airflow/.local/lib/python3.8/site-packages/google/api_core/retry/retry_base.py", line 212, in _retry_error_helper
    raise final_exc from source_exc
  File "/home/airflow/.local/lib/python3.8/site-packages/google/api_core/retry/retry_unary.py", line 144, in retry_target
    result = target()
  File "/home/airflow/.local/lib/python3.8/site-packages/google/cloud/_http/__init__.py", line 494, in api_request
    raise exceptions.from_http_response(response)
google.api_core.exceptions.NotFound: 404 POST https://bigquery.googleapis.com/bigquery/v2/projects/used-car-analysis/jobs?prettyPrint=false: Not found: Dataset used-car-analysis:used_car_data_price
[2024-03-19T01:57:09.532+0000] {taskinstance.py:1149} INFO - Marking task as FAILED. dag_id=source_to_gcs, task_id=Create_bigQuery_table, execution_date=20240319T014733, start_date=20240319T015708, end_date=20240319T015709
[2024-03-19T01:57:09.550+0000] {standard_task_runner.py:107} ERROR - Failed to execute job 88 for task Create_bigQuery_table (404 POST https://bigquery.googleapis.com/bigquery/v2/projects/used-car-analysis/jobs?prettyPrint=false: Not found: Dataset used-car-analysis:used_car_data_price; 537)
[2024-03-19T01:57:09.576+0000] {local_task_job_runner.py:234} INFO - Task exited with return code 1
[2024-03-19T01:57:09.601+0000] {taskinstance.py:3312} INFO - 0 downstream tasks scheduled from follow-on schedule check
