[2024-03-15T15:15:39.999+0000] {taskinstance.py:1979} INFO - Dependencies all met for dep_context=non-requeueable deps ti=<TaskInstance: source_to_gcs.upload_file_gcs manual__2024-03-15T15:15:35.370492+00:00 [queued]>
[2024-03-15T15:15:40.010+0000] {taskinstance.py:1979} INFO - Dependencies all met for dep_context=requeueable deps ti=<TaskInstance: source_to_gcs.upload_file_gcs manual__2024-03-15T15:15:35.370492+00:00 [queued]>
[2024-03-15T15:15:40.011+0000] {taskinstance.py:2193} INFO - Starting attempt 1 of 1
[2024-03-15T15:15:40.030+0000] {taskinstance.py:2217} INFO - Executing <Task(LocalFilesystemToGCSOperator): upload_file_gcs> on 2024-03-15 15:15:35.370492+00:00
[2024-03-15T15:15:40.039+0000] {standard_task_runner.py:60} INFO - Started process 387 to run task
[2024-03-15T15:15:40.047+0000] {standard_task_runner.py:87} INFO - Running: ['***', 'tasks', 'run', 'source_to_gcs', 'upload_file_gcs', 'manual__2024-03-15T15:15:35.370492+00:00', '--job-id', '37', '--raw', '--subdir', 'DAGS_FOLDER/sourcetobucket.py', '--cfg-path', '/tmp/tmpzgyg19sq']
[2024-03-15T15:15:40.058+0000] {standard_task_runner.py:88} INFO - Job 37: Subtask upload_file_gcs
[2024-03-15T15:15:40.177+0000] {task_command.py:423} INFO - Running <TaskInstance: source_to_gcs.upload_file_gcs manual__2024-03-15T15:15:35.370492+00:00 [running]> on host 6619d7082abd
[2024-03-15T15:15:40.332+0000] {taskinstance.py:2513} INFO - Exporting env vars: AIRFLOW_CTX_DAG_OWNER='***' AIRFLOW_CTX_DAG_ID='source_to_gcs' AIRFLOW_CTX_TASK_ID='upload_file_gcs' AIRFLOW_CTX_EXECUTION_DATE='2024-03-15T15:15:35.370492+00:00' AIRFLOW_CTX_TRY_NUMBER='1' AIRFLOW_CTX_DAG_RUN_ID='manual__2024-03-15T15:15:35.370492+00:00'
[2024-03-15T15:15:40.362+0000] {connection.py:269} WARNING - Connection schemes (type: google_cloud_platform) shall not contain '_' according to RFC3986.
[2024-03-15T15:15:40.366+0000] {base.py:83} INFO - Using connection ID 'gcp_***_conn' for task execution.
[2024-03-15T15:15:40.368+0000] {taskinstance.py:2731} ERROR - Task failed with exception
Traceback (most recent call last):
  File "/home/airflow/.local/lib/python3.8/site-packages/airflow/models/taskinstance.py", line 444, in _execute_task
    result = _execute_callable(context=context, **execute_callable_kwargs)
  File "/home/airflow/.local/lib/python3.8/site-packages/airflow/models/taskinstance.py", line 414, in _execute_callable
    return execute_callable(context=context, **execute_callable_kwargs)
  File "/home/airflow/.local/lib/python3.8/site-packages/airflow/providers/google/cloud/transfers/local_to_gcs.py", line 97, in execute
    raise FileNotFoundError(self.src)
FileNotFoundError: data/hello.txt
[2024-03-15T15:15:40.381+0000] {taskinstance.py:1149} INFO - Marking task as FAILED. dag_id=source_to_gcs, task_id=upload_file_gcs, execution_date=20240315T151535, start_date=20240315T151539, end_date=20240315T151540
[2024-03-15T15:15:40.406+0000] {standard_task_runner.py:107} ERROR - Failed to execute job 37 for task upload_file_gcs (data/hello.txt; 387)
[2024-03-15T15:15:40.441+0000] {local_task_job_runner.py:234} INFO - Task exited with return code 1
[2024-03-15T15:15:40.471+0000] {taskinstance.py:3312} INFO - 0 downstream tasks scheduled from follow-on schedule check
