[2024-03-15T02:07:38.032+0000] {taskinstance.py:1979} INFO - Dependencies all met for dep_context=non-requeueable deps ti=<TaskInstance: source_to_gcs.upload_file_gcs manual__2024-03-15T02:00:49.960481+00:00 [queued]>
[2024-03-15T02:07:38.043+0000] {taskinstance.py:1979} INFO - Dependencies all met for dep_context=requeueable deps ti=<TaskInstance: source_to_gcs.upload_file_gcs manual__2024-03-15T02:00:49.960481+00:00 [queued]>
[2024-03-15T02:07:38.044+0000] {taskinstance.py:2193} INFO - Starting attempt 4 of 4
[2024-03-15T02:07:38.062+0000] {taskinstance.py:2217} INFO - Executing <Task(LocalFilesystemToGCSOperator): upload_file_gcs> on 2024-03-15 02:00:49.960481+00:00
[2024-03-15T02:07:38.071+0000] {standard_task_runner.py:60} INFO - Started process 472 to run task
[2024-03-15T02:07:38.079+0000] {standard_task_runner.py:87} INFO - Running: ['***', 'tasks', 'run', 'source_to_gcs', 'upload_file_gcs', 'manual__2024-03-15T02:00:49.960481+00:00', '--job-id', '18', '--raw', '--subdir', 'DAGS_FOLDER/sourcetobucket.py', '--cfg-path', '/tmp/tmp1y_f1a2t']
[2024-03-15T02:07:38.083+0000] {standard_task_runner.py:88} INFO - Job 18: Subtask upload_file_gcs
[2024-03-15T02:07:38.172+0000] {task_command.py:423} INFO - Running <TaskInstance: source_to_gcs.upload_file_gcs manual__2024-03-15T02:00:49.960481+00:00 [running]> on host 693aecab9d7c
[2024-03-15T02:07:38.304+0000] {taskinstance.py:2513} INFO - Exporting env vars: AIRFLOW_CTX_DAG_OWNER='***' AIRFLOW_CTX_DAG_ID='source_to_gcs' AIRFLOW_CTX_TASK_ID='upload_file_gcs' AIRFLOW_CTX_EXECUTION_DATE='2024-03-15T02:00:49.960481+00:00' AIRFLOW_CTX_TRY_NUMBER='4' AIRFLOW_CTX_DAG_RUN_ID='manual__2024-03-15T02:00:49.960481+00:00'
[2024-03-15T02:07:38.321+0000] {connection.py:269} WARNING - Connection schemes (type: google_cloud_platform) shall not contain '_' according to RFC3986.
[2024-03-15T02:07:38.323+0000] {base.py:83} INFO - Using connection ID 'gcp_***_conn' for task execution.
[2024-03-15T02:07:38.324+0000] {taskinstance.py:2731} ERROR - Task failed with exception
Traceback (most recent call last):
  File "/home/airflow/.local/lib/python3.8/site-packages/airflow/models/taskinstance.py", line 444, in _execute_task
    result = _execute_callable(context=context, **execute_callable_kwargs)
  File "/home/airflow/.local/lib/python3.8/site-packages/airflow/models/taskinstance.py", line 414, in _execute_callable
    return execute_callable(context=context, **execute_callable_kwargs)
  File "/home/airflow/.local/lib/python3.8/site-packages/airflow/providers/google/cloud/transfers/local_to_gcs.py", line 97, in execute
    raise FileNotFoundError(self.src)
FileNotFoundError: ../Dockerfile
[2024-03-15T02:07:38.342+0000] {taskinstance.py:1149} INFO - Marking task as FAILED. dag_id=source_to_gcs, task_id=upload_file_gcs, execution_date=20240315T020049, start_date=20240315T020738, end_date=20240315T020738
[2024-03-15T02:07:38.362+0000] {standard_task_runner.py:107} ERROR - Failed to execute job 18 for task upload_file_gcs (../Dockerfile; 472)
[2024-03-15T02:07:38.383+0000] {local_task_job_runner.py:234} INFO - Task exited with return code 1
[2024-03-15T02:07:38.410+0000] {taskinstance.py:3312} INFO - 0 downstream tasks scheduled from follow-on schedule check
