[2024-03-15T02:02:19.838+0000] {taskinstance.py:1979} INFO - Dependencies all met for dep_context=non-requeueable deps ti=<TaskInstance: source_to_gcs.upload_file_gcs manual__2024-03-15T02:00:49.960481+00:00 [queued]>
[2024-03-15T02:02:19.879+0000] {taskinstance.py:1979} INFO - Dependencies all met for dep_context=requeueable deps ti=<TaskInstance: source_to_gcs.upload_file_gcs manual__2024-03-15T02:00:49.960481+00:00 [queued]>
[2024-03-15T02:02:19.880+0000] {taskinstance.py:2193} INFO - Starting attempt 2 of 2
[2024-03-15T02:02:19.931+0000] {taskinstance.py:2217} INFO - Executing <Task(LocalFilesystemToGCSOperator): upload_file_gcs> on 2024-03-15 02:00:49.960481+00:00
[2024-03-15T02:02:19.950+0000] {standard_task_runner.py:60} INFO - Started process 404 to run task
[2024-03-15T02:02:19.972+0000] {standard_task_runner.py:87} INFO - Running: ['***', 'tasks', 'run', 'source_to_gcs', 'upload_file_gcs', 'manual__2024-03-15T02:00:49.960481+00:00', '--job-id', '16', '--raw', '--subdir', 'DAGS_FOLDER/sourcetobucket.py', '--cfg-path', '/tmp/tmpxp5wowff']
[2024-03-15T02:02:19.984+0000] {standard_task_runner.py:88} INFO - Job 16: Subtask upload_file_gcs
[2024-03-15T02:02:20.123+0000] {task_command.py:423} INFO - Running <TaskInstance: source_to_gcs.upload_file_gcs manual__2024-03-15T02:00:49.960481+00:00 [running]> on host 693aecab9d7c
[2024-03-15T02:02:20.402+0000] {taskinstance.py:2513} INFO - Exporting env vars: AIRFLOW_CTX_DAG_OWNER='***' AIRFLOW_CTX_DAG_ID='source_to_gcs' AIRFLOW_CTX_TASK_ID='upload_file_gcs' AIRFLOW_CTX_EXECUTION_DATE='2024-03-15T02:00:49.960481+00:00' AIRFLOW_CTX_TRY_NUMBER='2' AIRFLOW_CTX_DAG_RUN_ID='manual__2024-03-15T02:00:49.960481+00:00'
[2024-03-15T02:02:20.424+0000] {connection.py:269} WARNING - Connection schemes (type: google_cloud_platform) shall not contain '_' according to RFC3986.
[2024-03-15T02:02:20.428+0000] {base.py:83} INFO - Using connection ID 'gcp_***_conn' for task execution.
[2024-03-15T02:02:20.431+0000] {taskinstance.py:2731} ERROR - Task failed with exception
Traceback (most recent call last):
  File "/home/airflow/.local/lib/python3.8/site-packages/airflow/models/taskinstance.py", line 444, in _execute_task
    result = _execute_callable(context=context, **execute_callable_kwargs)
  File "/home/airflow/.local/lib/python3.8/site-packages/airflow/models/taskinstance.py", line 414, in _execute_callable
    return execute_callable(context=context, **execute_callable_kwargs)
  File "/home/airflow/.local/lib/python3.8/site-packages/airflow/providers/google/cloud/transfers/local_to_gcs.py", line 97, in execute
    raise FileNotFoundError(self.src)
FileNotFoundError: ./data/raw/test.txt
[2024-03-15T02:02:20.454+0000] {taskinstance.py:1149} INFO - Marking task as FAILED. dag_id=source_to_gcs, task_id=upload_file_gcs, execution_date=20240315T020049, start_date=20240315T020219, end_date=20240315T020220
[2024-03-15T02:02:20.483+0000] {standard_task_runner.py:107} ERROR - Failed to execute job 16 for task upload_file_gcs (./data/raw/test.txt; 404)
[2024-03-15T02:02:20.509+0000] {local_task_job_runner.py:234} INFO - Task exited with return code 1
[2024-03-15T02:02:20.571+0000] {taskinstance.py:3312} INFO - 0 downstream tasks scheduled from follow-on schedule check
