[2024-03-23T05:02:33.054+0000] {taskinstance.py:1979} INFO - Dependencies all met for dep_context=non-requeueable deps ti=<TaskInstance: source_to_gcs.get_check_result manual__2024-03-23T04:37:37.326228+00:00 [queued]>
[2024-03-23T05:02:33.070+0000] {taskinstance.py:1979} INFO - Dependencies all met for dep_context=requeueable deps ti=<TaskInstance: source_to_gcs.get_check_result manual__2024-03-23T04:37:37.326228+00:00 [queued]>
[2024-03-23T05:02:33.071+0000] {taskinstance.py:2193} INFO - Starting attempt 2 of 2
[2024-03-23T05:02:33.094+0000] {taskinstance.py:2217} INFO - Executing <Task(PythonOperator): get_check_result> on 2024-03-23 04:37:37.326228+00:00
[2024-03-23T05:02:33.104+0000] {standard_task_runner.py:60} INFO - Started process 113 to run task
[2024-03-23T05:02:33.112+0000] {standard_task_runner.py:87} INFO - Running: ['***', 'tasks', 'run', 'source_to_gcs', 'get_check_result', 'manual__2024-03-23T04:37:37.326228+00:00', '--job-id', '190', '--raw', '--subdir', 'DAGS_FOLDER/sourcetobucket.py', '--cfg-path', '/tmp/tmpjhnc2u7_']
[2024-03-23T05:02:33.118+0000] {standard_task_runner.py:88} INFO - Job 190: Subtask get_check_result
[2024-03-23T05:02:33.197+0000] {task_command.py:423} INFO - Running <TaskInstance: source_to_gcs.get_check_result manual__2024-03-23T04:37:37.326228+00:00 [running]> on host ceb99a37e23c
[2024-03-23T05:02:33.386+0000] {taskinstance.py:2513} INFO - Exporting env vars: AIRFLOW_CTX_DAG_OWNER='***' AIRFLOW_CTX_DAG_ID='source_to_gcs' AIRFLOW_CTX_TASK_ID='get_check_result' AIRFLOW_CTX_EXECUTION_DATE='2024-03-23T04:37:37.326228+00:00' AIRFLOW_CTX_TRY_NUMBER='2' AIRFLOW_CTX_DAG_RUN_ID='manual__2024-03-23T04:37:37.326228+00:00'
[2024-03-23T05:02:33.391+0000] {taskinstance.py:2731} ERROR - Task failed with exception
Traceback (most recent call last):
  File "/home/airflow/.local/lib/python3.8/site-packages/airflow/models/taskinstance.py", line 444, in _execute_task
    result = _execute_callable(context=context, **execute_callable_kwargs)
  File "/home/airflow/.local/lib/python3.8/site-packages/airflow/models/taskinstance.py", line 414, in _execute_callable
    return execute_callable(context=context, **execute_callable_kwargs)
  File "/home/airflow/.local/lib/python3.8/site-packages/airflow/operators/python.py", line 200, in execute
    return_value = self.execute_callable()
  File "/home/airflow/.local/lib/python3.8/site-packages/airflow/operators/python.py", line 217, in execute_callable
    return self.python_callable(*self.op_args, **self.op_kwargs)
  File "/opt/airflow/dags/sourcetobucket.py", line 65, in run_bigquery_check
    if check_file():
TypeError: 'BigQueryCheckOperator' object is not callable
[2024-03-23T05:02:33.431+0000] {taskinstance.py:1149} INFO - Marking task as FAILED. dag_id=source_to_gcs, task_id=get_check_result, execution_date=20240323T043737, start_date=20240323T050233, end_date=20240323T050233
[2024-03-23T05:02:33.491+0000] {standard_task_runner.py:107} ERROR - Failed to execute job 190 for task get_check_result ('BigQueryCheckOperator' object is not callable; 113)
[2024-03-23T05:02:33.527+0000] {local_task_job_runner.py:234} INFO - Task exited with return code 1
[2024-03-23T05:02:33.551+0000] {taskinstance.py:3312} INFO - 0 downstream tasks scheduled from follow-on schedule check
