[2024-03-23T04:37:39.178+0000] {taskinstance.py:1979} INFO - Dependencies all met for dep_context=non-requeueable deps ti=<TaskInstance: source_to_gcs.get_data_from_source manual__2024-03-23T04:37:37.326228+00:00 [queued]>
[2024-03-23T04:37:39.190+0000] {taskinstance.py:1979} INFO - Dependencies all met for dep_context=requeueable deps ti=<TaskInstance: source_to_gcs.get_data_from_source manual__2024-03-23T04:37:37.326228+00:00 [queued]>
[2024-03-23T04:37:39.191+0000] {taskinstance.py:2193} INFO - Starting attempt 1 of 1
[2024-03-23T04:37:39.213+0000] {taskinstance.py:2217} INFO - Executing <Task(_PythonDecoratedOperator): get_data_from_source> on 2024-03-23 04:37:37.326228+00:00
[2024-03-23T04:37:39.223+0000] {standard_task_runner.py:60} INFO - Started process 165 to run task
[2024-03-23T04:37:39.230+0000] {standard_task_runner.py:87} INFO - Running: ['***', 'tasks', 'run', 'source_to_gcs', 'get_data_from_source', 'manual__2024-03-23T04:37:37.326228+00:00', '--job-id', '183', '--raw', '--subdir', 'DAGS_FOLDER/sourcetobucket.py', '--cfg-path', '/tmp/tmp0dy9gixw']
[2024-03-23T04:37:39.235+0000] {standard_task_runner.py:88} INFO - Job 183: Subtask get_data_from_source
[2024-03-23T04:37:39.306+0000] {task_command.py:423} INFO - Running <TaskInstance: source_to_gcs.get_data_from_source manual__2024-03-23T04:37:37.326228+00:00 [running]> on host ceb99a37e23c
[2024-03-23T04:37:39.424+0000] {taskinstance.py:2513} INFO - Exporting env vars: AIRFLOW_CTX_DAG_OWNER='***' AIRFLOW_CTX_DAG_ID='source_to_gcs' AIRFLOW_CTX_TASK_ID='get_data_from_source' AIRFLOW_CTX_EXECUTION_DATE='2024-03-23T04:37:37.326228+00:00' AIRFLOW_CTX_TRY_NUMBER='1' AIRFLOW_CTX_DAG_RUN_ID='manual__2024-03-23T04:37:37.326228+00:00'
[2024-03-23T04:37:54.030+0000] {taskinstance.py:2731} ERROR - Task failed with exception
Traceback (most recent call last):
  File "/home/airflow/.local/lib/python3.8/site-packages/airflow/models/taskinstance.py", line 444, in _execute_task
    result = _execute_callable(context=context, **execute_callable_kwargs)
  File "/home/airflow/.local/lib/python3.8/site-packages/airflow/models/taskinstance.py", line 414, in _execute_callable
    return execute_callable(context=context, **execute_callable_kwargs)
  File "/home/airflow/.local/lib/python3.8/site-packages/airflow/decorators/base.py", line 241, in execute
    return_value = super().execute(context)
  File "/home/airflow/.local/lib/python3.8/site-packages/airflow/operators/python.py", line 200, in execute
    return_value = self.execute_callable()
  File "/home/airflow/.local/lib/python3.8/site-packages/airflow/operators/python.py", line 217, in execute_callable
    return self.python_callable(*self.op_args, **self.op_kwargs)
  File "/opt/airflow/dags/sourcetobucket.py", line 40, in get_data_from_source
    state_abb_data_csv = pd.read_csv("https://github.com/Hari-cbe/Random-resourses/blob/main/Used-car-price-data/data_raw_state_abbrivation.csv"
  File "/home/airflow/.local/lib/python3.8/site-packages/pandas/io/parsers/readers.py", line 912, in read_csv
    return _read(filepath_or_buffer, kwds)
  File "/home/airflow/.local/lib/python3.8/site-packages/pandas/io/parsers/readers.py", line 583, in _read
    return parser.read(nrows)
  File "/home/airflow/.local/lib/python3.8/site-packages/pandas/io/parsers/readers.py", line 1704, in read
    ) = self._engine.read(  # type: ignore[attr-defined]
  File "/home/airflow/.local/lib/python3.8/site-packages/pandas/io/parsers/c_parser_wrapper.py", line 234, in read
    chunks = self._reader.read_low_memory(nrows)
  File "pandas/_libs/parsers.pyx", line 812, in pandas._libs.parsers.TextReader.read_low_memory
  File "pandas/_libs/parsers.pyx", line 873, in pandas._libs.parsers.TextReader._read_rows
  File "pandas/_libs/parsers.pyx", line 848, in pandas._libs.parsers.TextReader._tokenize_rows
  File "pandas/_libs/parsers.pyx", line 859, in pandas._libs.parsers.TextReader._check_tokenize_status
  File "pandas/_libs/parsers.pyx", line 2025, in pandas._libs.parsers.raise_parser_error
pandas.errors.ParserError: Error tokenizing data. C error: Expected 1 fields in line 41, saw 18

[2024-03-23T04:37:54.115+0000] {taskinstance.py:1149} INFO - Marking task as FAILED. dag_id=source_to_gcs, task_id=get_data_from_source, execution_date=20240323T043737, start_date=20240323T043739, end_date=20240323T043754
[2024-03-23T04:37:54.202+0000] {standard_task_runner.py:107} ERROR - Failed to execute job 183 for task get_data_from_source (Error tokenizing data. C error: Expected 1 fields in line 41, saw 18
; 165)
[2024-03-23T04:37:54.339+0000] {local_task_job_runner.py:234} INFO - Task exited with return code 1
[2024-03-23T04:37:54.508+0000] {taskinstance.py:3312} INFO - 0 downstream tasks scheduled from follow-on schedule check
