[2024-03-23T05:13:17.046+0000] {taskinstance.py:1979} INFO - Dependencies all met for dep_context=non-requeueable deps ti=<TaskInstance: source_to_gcs.choose_task manual__2024-03-23T05:12:43.908890+00:00 [queued]>
[2024-03-23T05:13:17.068+0000] {taskinstance.py:1979} INFO - Dependencies all met for dep_context=requeueable deps ti=<TaskInstance: source_to_gcs.choose_task manual__2024-03-23T05:12:43.908890+00:00 [queued]>
[2024-03-23T05:13:17.069+0000] {taskinstance.py:2193} INFO - Starting attempt 1 of 1
[2024-03-23T05:13:17.107+0000] {taskinstance.py:2217} INFO - Executing <Task(_BranchPythonDecoratedOperator): choose_task> on 2024-03-23 05:12:43.908890+00:00
[2024-03-23T05:13:17.120+0000] {standard_task_runner.py:60} INFO - Started process 271 to run task
[2024-03-23T05:13:17.136+0000] {standard_task_runner.py:87} INFO - Running: ['***', 'tasks', 'run', 'source_to_gcs', 'choose_task', 'manual__2024-03-23T05:12:43.908890+00:00', '--job-id', '195', '--raw', '--subdir', 'DAGS_FOLDER/sourcetobucket.py', '--cfg-path', '/tmp/tmpobql581w']
[2024-03-23T05:13:17.143+0000] {standard_task_runner.py:88} INFO - Job 195: Subtask choose_task
[2024-03-23T05:13:17.262+0000] {task_command.py:423} INFO - Running <TaskInstance: source_to_gcs.choose_task manual__2024-03-23T05:12:43.908890+00:00 [running]> on host ceb99a37e23c
[2024-03-23T05:13:17.556+0000] {taskinstance.py:2513} INFO - Exporting env vars: AIRFLOW_CTX_DAG_OWNER='***' AIRFLOW_CTX_DAG_ID='source_to_gcs' AIRFLOW_CTX_TASK_ID='choose_task' AIRFLOW_CTX_EXECUTION_DATE='2024-03-23T05:12:43.908890+00:00' AIRFLOW_CTX_TRY_NUMBER='1' AIRFLOW_CTX_DAG_RUN_ID='manual__2024-03-23T05:12:43.908890+00:00'
[2024-03-23T05:13:17.569+0000] {taskinstance.py:2731} ERROR - Task failed with exception
Traceback (most recent call last):
  File "/home/airflow/.local/lib/python3.8/site-packages/airflow/models/taskinstance.py", line 444, in _execute_task
    result = _execute_callable(context=context, **execute_callable_kwargs)
  File "/home/airflow/.local/lib/python3.8/site-packages/airflow/models/taskinstance.py", line 414, in _execute_callable
    return execute_callable(context=context, **execute_callable_kwargs)
  File "/home/airflow/.local/lib/python3.8/site-packages/airflow/decorators/base.py", line 241, in execute
    return_value = super().execute(context)
  File "/home/airflow/.local/lib/python3.8/site-packages/airflow/operators/python.py", line 234, in execute
    return self.do_branch(context, super().execute(context))
  File "/home/airflow/.local/lib/python3.8/site-packages/airflow/operators/python.py", line 200, in execute
    return_value = self.execute_callable()
  File "/home/airflow/.local/lib/python3.8/site-packages/airflow/operators/python.py", line 217, in execute_callable
    return self.python_callable(*self.op_args, **self.op_kwargs)
  File "/opt/airflow/dags/sourcetobucket.py", line 80, in choose_task
    if get_check_result.lower() == "success":
AttributeError: 'PythonOperator' object has no attribute 'lower'
[2024-03-23T05:13:17.602+0000] {taskinstance.py:1149} INFO - Marking task as FAILED. dag_id=source_to_gcs, task_id=choose_task, execution_date=20240323T051243, start_date=20240323T051317, end_date=20240323T051317
[2024-03-23T05:13:17.636+0000] {standard_task_runner.py:107} ERROR - Failed to execute job 195 for task choose_task ('PythonOperator' object has no attribute 'lower'; 271)
[2024-03-23T05:13:17.676+0000] {local_task_job_runner.py:234} INFO - Task exited with return code 1
[2024-03-23T05:13:17.744+0000] {taskinstance.py:3312} INFO - 0 downstream tasks scheduled from follow-on schedule check
