[2024-03-19T01:46:19.111+0000] {taskinstance.py:1979} INFO - Dependencies all met for dep_context=non-requeueable deps ti=<TaskInstance: source_to_gcs.Create_bigQuery_table manual__2024-03-19T01:46:05.315533+00:00 [queued]>
[2024-03-19T01:46:19.128+0000] {taskinstance.py:1979} INFO - Dependencies all met for dep_context=requeueable deps ti=<TaskInstance: source_to_gcs.Create_bigQuery_table manual__2024-03-19T01:46:05.315533+00:00 [queued]>
[2024-03-19T01:46:19.129+0000] {taskinstance.py:2193} INFO - Starting attempt 1 of 1
[2024-03-19T01:46:19.149+0000] {taskinstance.py:2217} INFO - Executing <Task(BigQueryCreateExternalTableOperator): Create_bigQuery_table> on 2024-03-19 01:46:05.315533+00:00
[2024-03-19T01:46:19.159+0000] {standard_task_runner.py:60} INFO - Started process 371 to run task
[2024-03-19T01:46:19.166+0000] {standard_task_runner.py:87} INFO - Running: ['***', 'tasks', 'run', 'source_to_gcs', 'Create_bigQuery_table', 'manual__2024-03-19T01:46:05.315533+00:00', '--job-id', '83', '--raw', '--subdir', 'DAGS_FOLDER/sourcetobucket.py', '--cfg-path', '/tmp/tmpfleecr3g']
[2024-03-19T01:46:19.170+0000] {standard_task_runner.py:88} INFO - Job 83: Subtask Create_bigQuery_table
[2024-03-19T01:46:19.246+0000] {task_command.py:423} INFO - Running <TaskInstance: source_to_gcs.Create_bigQuery_table manual__2024-03-19T01:46:05.315533+00:00 [running]> on host 484fbc655ee6
[2024-03-19T01:46:19.373+0000] {taskinstance.py:2513} INFO - Exporting env vars: AIRFLOW_CTX_DAG_OWNER='***' AIRFLOW_CTX_DAG_ID='source_to_gcs' AIRFLOW_CTX_TASK_ID='Create_bigQuery_table' AIRFLOW_CTX_EXECUTION_DATE='2024-03-19T01:46:05.315533+00:00' AIRFLOW_CTX_TRY_NUMBER='1' AIRFLOW_CTX_DAG_RUN_ID='manual__2024-03-19T01:46:05.315533+00:00'
[2024-03-19T01:46:19.401+0000] {taskinstance.py:2731} ERROR - Task failed with exception
Traceback (most recent call last):
  File "/home/airflow/.local/lib/python3.8/site-packages/airflow/models/taskinstance.py", line 444, in _execute_task
    result = _execute_callable(context=context, **execute_callable_kwargs)
  File "/home/airflow/.local/lib/python3.8/site-packages/airflow/models/taskinstance.py", line 414, in _execute_callable
    return execute_callable(context=context, **execute_callable_kwargs)
  File "/home/airflow/.local/lib/python3.8/site-packages/airflow/providers/google/cloud/operators/bigquery.py", line 1777, in execute
    bq_hook = BigQueryHook(
  File "/home/airflow/.local/lib/python3.8/site-packages/airflow/providers/google/cloud/hooks/bigquery.py", line 119, in __init__
    super().__init__(
  File "/home/airflow/.local/lib/python3.8/site-packages/airflow/providers/google/common/hooks/base_google.py", line 251, in __init__
    self.extras: dict = self.get_connection(self.gcp_conn_id).extra_dejson
  File "/home/airflow/.local/lib/python3.8/site-packages/airflow/hooks/base.py", line 82, in get_connection
    conn = Connection.get_connection_from_secrets(conn_id)
  File "/home/airflow/.local/lib/python3.8/site-packages/airflow/models/connection.py", line 514, in get_connection_from_secrets
    raise AirflowNotFoundException(f"The conn_id `{conn_id}` isn't defined")
airflow.exceptions.AirflowNotFoundException: The conn_id `google_cloud_default` isn't defined
[2024-03-19T01:46:19.464+0000] {taskinstance.py:1149} INFO - Marking task as FAILED. dag_id=source_to_gcs, task_id=Create_bigQuery_table, execution_date=20240319T014605, start_date=20240319T014619, end_date=20240319T014619
[2024-03-19T01:46:19.521+0000] {standard_task_runner.py:107} ERROR - Failed to execute job 83 for task Create_bigQuery_table (The conn_id `google_cloud_default` isn't defined; 371)
[2024-03-19T01:46:19.540+0000] {local_task_job_runner.py:234} INFO - Task exited with return code 1
[2024-03-19T01:46:19.567+0000] {taskinstance.py:3312} INFO - 0 downstream tasks scheduled from follow-on schedule check
