[2024-03-22T01:46:04.204+0000] {taskinstance.py:1979} INFO - Dependencies all met for dep_context=non-requeueable deps ti=<TaskInstance: source_to_gcs.get_data_from_source manual__2024-03-22T01:46:00.022977+00:00 [queued]>
[2024-03-22T01:46:04.223+0000] {taskinstance.py:1979} INFO - Dependencies all met for dep_context=requeueable deps ti=<TaskInstance: source_to_gcs.get_data_from_source manual__2024-03-22T01:46:00.022977+00:00 [queued]>
[2024-03-22T01:46:04.224+0000] {taskinstance.py:2193} INFO - Starting attempt 1 of 1
[2024-03-22T01:46:04.251+0000] {taskinstance.py:2217} INFO - Executing <Task(_PythonDecoratedOperator): get_data_from_source> on 2024-03-22 01:46:00.022977+00:00
[2024-03-22T01:46:04.261+0000] {standard_task_runner.py:60} INFO - Started process 583 to run task
[2024-03-22T01:46:04.269+0000] {standard_task_runner.py:87} INFO - Running: ['***', 'tasks', 'run', 'source_to_gcs', 'get_data_from_source', 'manual__2024-03-22T01:46:00.022977+00:00', '--job-id', '133', '--raw', '--subdir', 'DAGS_FOLDER/sourcetobucket.py', '--cfg-path', '/tmp/tmp9hfbpf2g']
[2024-03-22T01:46:04.274+0000] {standard_task_runner.py:88} INFO - Job 133: Subtask get_data_from_source
[2024-03-22T01:46:04.374+0000] {task_command.py:423} INFO - Running <TaskInstance: source_to_gcs.get_data_from_source manual__2024-03-22T01:46:00.022977+00:00 [running]> on host 2d773125f5e6
[2024-03-22T01:46:04.513+0000] {taskinstance.py:2513} INFO - Exporting env vars: AIRFLOW_CTX_DAG_OWNER='***' AIRFLOW_CTX_DAG_ID='source_to_gcs' AIRFLOW_CTX_TASK_ID='get_data_from_source' AIRFLOW_CTX_EXECUTION_DATE='2024-03-22T01:46:00.022977+00:00' AIRFLOW_CTX_TRY_NUMBER='1' AIRFLOW_CTX_DAG_RUN_ID='manual__2024-03-22T01:46:00.022977+00:00'
[2024-03-22T01:46:04.865+0000] {logging_mixin.py:188} INFO - Failed to download CSV file. Status code: 404
[2024-03-22T01:46:05.145+0000] {taskinstance.py:2731} ERROR - Task failed with exception
Traceback (most recent call last):
  File "/home/airflow/.local/lib/python3.8/site-packages/airflow/models/taskinstance.py", line 444, in _execute_task
    result = _execute_callable(context=context, **execute_callable_kwargs)
  File "/home/airflow/.local/lib/python3.8/site-packages/airflow/models/taskinstance.py", line 414, in _execute_callable
    return execute_callable(context=context, **execute_callable_kwargs)
  File "/home/airflow/.local/lib/python3.8/site-packages/airflow/decorators/base.py", line 241, in execute
    return_value = super().execute(context)
  File "/home/airflow/.local/lib/python3.8/site-packages/airflow/operators/python.py", line 200, in execute
    return_value = self.execute_callable()
  File "/home/airflow/.local/lib/python3.8/site-packages/airflow/operators/python.py", line 217, in execute_callable
    return self.python_callable(*self.op_args, **self.op_kwargs)
  File "/opt/airflow/dags/sourcetobucket.py", line 46, in get_data_from_source
    with open("../data/state_abb_data.csv", "wb") as f:
FileNotFoundError: [Errno 2] No such file or directory: '../data/state_abb_data.csv'
[2024-03-22T01:46:05.198+0000] {taskinstance.py:1149} INFO - Marking task as FAILED. dag_id=source_to_gcs, task_id=get_data_from_source, execution_date=20240322T014600, start_date=20240322T014604, end_date=20240322T014605
[2024-03-22T01:46:05.255+0000] {standard_task_runner.py:107} ERROR - Failed to execute job 133 for task get_data_from_source ([Errno 2] No such file or directory: '../data/state_abb_data.csv'; 583)
[2024-03-22T01:46:05.290+0000] {local_task_job_runner.py:234} INFO - Task exited with return code 1
[2024-03-22T01:46:05.333+0000] {taskinstance.py:3312} INFO - 0 downstream tasks scheduled from follow-on schedule check
