[2024-03-22T01:47:46.627+0000] {taskinstance.py:1979} INFO - Dependencies all met for dep_context=non-requeueable deps ti=<TaskInstance: source_to_gcs.get_data_from_source manual__2024-03-22T01:46:00.022977+00:00 [queued]>
[2024-03-22T01:47:46.644+0000] {taskinstance.py:1979} INFO - Dependencies all met for dep_context=requeueable deps ti=<TaskInstance: source_to_gcs.get_data_from_source manual__2024-03-22T01:46:00.022977+00:00 [queued]>
[2024-03-22T01:47:46.645+0000] {taskinstance.py:2193} INFO - Starting attempt 2 of 2
[2024-03-22T01:47:46.675+0000] {taskinstance.py:2217} INFO - Executing <Task(_PythonDecoratedOperator): get_data_from_source> on 2024-03-22 01:46:00.022977+00:00
[2024-03-22T01:47:46.687+0000] {standard_task_runner.py:60} INFO - Started process 609 to run task
[2024-03-22T01:47:46.697+0000] {standard_task_runner.py:87} INFO - Running: ['***', 'tasks', 'run', 'source_to_gcs', 'get_data_from_source', 'manual__2024-03-22T01:46:00.022977+00:00', '--job-id', '134', '--raw', '--subdir', 'DAGS_FOLDER/sourcetobucket.py', '--cfg-path', '/tmp/tmp7ba_j2o6']
[2024-03-22T01:47:46.703+0000] {standard_task_runner.py:88} INFO - Job 134: Subtask get_data_from_source
[2024-03-22T01:47:46.785+0000] {task_command.py:423} INFO - Running <TaskInstance: source_to_gcs.get_data_from_source manual__2024-03-22T01:46:00.022977+00:00 [running]> on host 2d773125f5e6
[2024-03-22T01:47:46.928+0000] {taskinstance.py:2513} INFO - Exporting env vars: AIRFLOW_CTX_DAG_OWNER='***' AIRFLOW_CTX_DAG_ID='source_to_gcs' AIRFLOW_CTX_TASK_ID='get_data_from_source' AIRFLOW_CTX_EXECUTION_DATE='2024-03-22T01:46:00.022977+00:00' AIRFLOW_CTX_TRY_NUMBER='2' AIRFLOW_CTX_DAG_RUN_ID='manual__2024-03-22T01:46:00.022977+00:00'
[2024-03-22T01:47:47.268+0000] {logging_mixin.py:188} INFO - Failed to download CSV file. Status code: 404
[2024-03-22T01:47:47.496+0000] {taskinstance.py:2731} ERROR - Task failed with exception
Traceback (most recent call last):
  File "/home/airflow/.local/lib/python3.8/site-packages/airflow/models/taskinstance.py", line 444, in _execute_task
    result = _execute_callable(context=context, **execute_callable_kwargs)
  File "/home/airflow/.local/lib/python3.8/site-packages/airflow/models/taskinstance.py", line 414, in _execute_callable
    return execute_callable(context=context, **execute_callable_kwargs)
  File "/home/airflow/.local/lib/python3.8/site-packages/airflow/decorators/base.py", line 241, in execute
    return_value = super().execute(context)
  File "/home/airflow/.local/lib/python3.8/site-packages/airflow/operators/python.py", line 200, in execute
    return_value = self.execute_callable()
  File "/home/airflow/.local/lib/python3.8/site-packages/airflow/operators/python.py", line 217, in execute_callable
    return self.python_callable(*self.op_args, **self.op_kwargs)
  File "/opt/airflow/dags/sourcetobucket.py", line 46, in get_data_from_source
    with open("/data/state_abb_data.csv", "wb") as f:
FileNotFoundError: [Errno 2] No such file or directory: '/data/state_abb_data.csv'
[2024-03-22T01:47:47.509+0000] {taskinstance.py:1149} INFO - Marking task as FAILED. dag_id=source_to_gcs, task_id=get_data_from_source, execution_date=20240322T014600, start_date=20240322T014746, end_date=20240322T014747
[2024-03-22T01:47:47.533+0000] {standard_task_runner.py:107} ERROR - Failed to execute job 134 for task get_data_from_source ([Errno 2] No such file or directory: '/data/state_abb_data.csv'; 609)
[2024-03-22T01:47:47.568+0000] {local_task_job_runner.py:234} INFO - Task exited with return code 1
[2024-03-22T01:47:47.607+0000] {taskinstance.py:3312} INFO - 0 downstream tasks scheduled from follow-on schedule check
