[2024-03-19T02:09:13.524+0000] {taskinstance.py:1979} INFO - Dependencies all met for dep_context=non-requeueable deps ti=<TaskInstance: source_to_gcs.insert_data_into_table manual__2024-03-19T01:47:33.877964+00:00 [queued]>
[2024-03-19T02:09:13.540+0000] {taskinstance.py:1979} INFO - Dependencies all met for dep_context=requeueable deps ti=<TaskInstance: source_to_gcs.insert_data_into_table manual__2024-03-19T01:47:33.877964+00:00 [queued]>
[2024-03-19T02:09:13.541+0000] {taskinstance.py:2193} INFO - Starting attempt 1 of 1
[2024-03-19T02:09:13.561+0000] {taskinstance.py:2217} INFO - Executing <Task(GCSToBigQueryOperator): insert_data_into_table> on 2024-03-19 01:47:33.877964+00:00
[2024-03-19T02:09:13.572+0000] {standard_task_runner.py:60} INFO - Started process 726 to run task
[2024-03-19T02:09:13.578+0000] {standard_task_runner.py:87} INFO - Running: ['***', 'tasks', 'run', 'source_to_gcs', 'insert_data_into_table', 'manual__2024-03-19T01:47:33.877964+00:00', '--job-id', '94', '--raw', '--subdir', 'DAGS_FOLDER/sourcetobucket.py', '--cfg-path', '/tmp/tmpwynvcreo']
[2024-03-19T02:09:13.583+0000] {standard_task_runner.py:88} INFO - Job 94: Subtask insert_data_into_table
[2024-03-19T02:09:13.674+0000] {task_command.py:423} INFO - Running <TaskInstance: source_to_gcs.insert_data_into_table manual__2024-03-19T01:47:33.877964+00:00 [running]> on host 484fbc655ee6
[2024-03-19T02:09:13.875+0000] {taskinstance.py:2513} INFO - Exporting env vars: AIRFLOW_CTX_DAG_OWNER='***' AIRFLOW_CTX_DAG_ID='source_to_gcs' AIRFLOW_CTX_TASK_ID='insert_data_into_table' AIRFLOW_CTX_EXECUTION_DATE='2024-03-19T01:47:33.877964+00:00' AIRFLOW_CTX_TRY_NUMBER='1' AIRFLOW_CTX_DAG_RUN_ID='manual__2024-03-19T01:47:33.877964+00:00'
[2024-03-19T02:09:13.967+0000] {connection.py:269} WARNING - Connection schemes (type: google_cloud_platform) shall not contain '_' according to RFC3986.
[2024-03-19T02:09:13.974+0000] {base.py:83} INFO - Using connection ID 'gcp_***_conn' for task execution.
[2024-03-19T02:09:13.987+0000] {gcs_to_bigquery.py:379} INFO - Using existing BigQuery table for storing data...
[2024-03-19T02:09:14.136+0000] {bigquery.py:2328} INFO - Project is not included in destination_project_dataset_table: used_car_analysis_dataset.used_car_price; using project "used-car-analysis"
[2024-03-19T02:09:14.137+0000] {gcs_to_bigquery.py:383} INFO - Executing: {'load': {'autodetect': True, 'createDisposition': 'CREATE_IF_NEEDED', 'destinationTable': {'projectId': 'used-car-analysis', 'datasetId': 'used_car_analysis_dataset', 'tableId': 'used_car_price'}, 'sourceFormat': 'CSV', 'sourceUris': ['gs://used-car-price-analysis/gs://used-car-price-analysis/data/raw/car_sales.csv'], 'writeDisposition': 'WRITE_EMPTY', 'ignoreUnknownValues': False, 'skipLeadingRows': None, 'fieldDelimiter': ',', 'quote': None, 'allowQuotedNewlines': False, 'encoding': 'UTF-8'}}
[2024-03-19T02:09:14.139+0000] {bigquery.py:1613} INFO - Inserting job ***_source_to_gcs_insert_data_into_table_2024_03_19T01_47_33_877964_00_00_70c7f48f210f2d028cf9a667f1ccc192
[2024-03-19T02:09:14.930+0000] {taskinstance.py:2731} ERROR - Task failed with exception
Traceback (most recent call last):
  File "/home/airflow/.local/lib/python3.8/site-packages/airflow/models/taskinstance.py", line 444, in _execute_task
    result = _execute_callable(context=context, **execute_callable_kwargs)
  File "/home/airflow/.local/lib/python3.8/site-packages/airflow/models/taskinstance.py", line 414, in _execute_callable
    return execute_callable(context=context, **execute_callable_kwargs)
  File "/home/airflow/.local/lib/python3.8/site-packages/airflow/providers/google/cloud/transfers/gcs_to_bigquery.py", line 444, in execute
    job.result(timeout=self.result_timeout, retry=self.result_retry)
  File "/home/airflow/.local/lib/python3.8/site-packages/google/cloud/bigquery/job/base.py", line 971, in result
    return super(_AsyncJob, self).result(timeout=timeout, **kwargs)
  File "/home/airflow/.local/lib/python3.8/site-packages/google/api_core/future/polling.py", line 261, in result
    raise self._exception
google.api_core.exceptions.NotFound: 404 Not found: URI gs://used-car-price-analysis/gs://used-car-price-analysis/data/raw/car_sales.csv; reason: notFound, message: Not found: URI gs://used-car-price-analysis/gs://used-car-price-analysis/data/raw/car_sales.csv
[2024-03-19T02:09:14.942+0000] {taskinstance.py:1149} INFO - Marking task as FAILED. dag_id=source_to_gcs, task_id=insert_data_into_table, execution_date=20240319T014733, start_date=20240319T020913, end_date=20240319T020914
[2024-03-19T02:09:14.960+0000] {standard_task_runner.py:107} ERROR - Failed to execute job 94 for task insert_data_into_table (404 Not found: URI gs://used-car-price-analysis/gs://used-car-price-analysis/data/raw/car_sales.csv; reason: notFound, message: Not found: URI gs://used-car-price-analysis/gs://used-car-price-analysis/data/raw/car_sales.csv; 726)
[2024-03-19T02:09:14.977+0000] {local_task_job_runner.py:234} INFO - Task exited with return code 1
[2024-03-19T02:09:15.003+0000] {taskinstance.py:3312} INFO - 0 downstream tasks scheduled from follow-on schedule check
