[2024-03-15T01:59:11.916+0000] {taskinstance.py:1979} INFO - Dependencies all met for dep_context=non-requeueable deps ti=<TaskInstance: source_to_gcs.upload_file_gcs manual__2024-03-15T01:57:59.266745+00:00 [queued]>
[2024-03-15T01:59:11.928+0000] {taskinstance.py:1979} INFO - Dependencies all met for dep_context=requeueable deps ti=<TaskInstance: source_to_gcs.upload_file_gcs manual__2024-03-15T01:57:59.266745+00:00 [queued]>
[2024-03-15T01:59:11.928+0000] {taskinstance.py:2193} INFO - Starting attempt 2 of 2
[2024-03-15T01:59:11.947+0000] {taskinstance.py:2217} INFO - Executing <Task(LocalFilesystemToGCSOperator): upload_file_gcs> on 2024-03-15 01:57:59.266745+00:00
[2024-03-15T01:59:11.956+0000] {standard_task_runner.py:60} INFO - Started process 349 to run task
[2024-03-15T01:59:11.964+0000] {standard_task_runner.py:87} INFO - Running: ['***', 'tasks', 'run', 'source_to_gcs', 'upload_file_gcs', 'manual__2024-03-15T01:57:59.266745+00:00', '--job-id', '13', '--raw', '--subdir', 'DAGS_FOLDER/sourcetobucket.py', '--cfg-path', '/tmp/tmpio06ew6d']
[2024-03-15T01:59:11.969+0000] {standard_task_runner.py:88} INFO - Job 13: Subtask upload_file_gcs
[2024-03-15T01:59:12.046+0000] {task_command.py:423} INFO - Running <TaskInstance: source_to_gcs.upload_file_gcs manual__2024-03-15T01:57:59.266745+00:00 [running]> on host 693aecab9d7c
[2024-03-15T01:59:12.183+0000] {taskinstance.py:2513} INFO - Exporting env vars: AIRFLOW_CTX_DAG_OWNER='***' AIRFLOW_CTX_DAG_ID='source_to_gcs' AIRFLOW_CTX_TASK_ID='upload_file_gcs' AIRFLOW_CTX_EXECUTION_DATE='2024-03-15T01:57:59.266745+00:00' AIRFLOW_CTX_TRY_NUMBER='2' AIRFLOW_CTX_DAG_RUN_ID='manual__2024-03-15T01:57:59.266745+00:00'
[2024-03-15T01:59:12.197+0000] {connection.py:269} WARNING - Connection schemes (type: google_cloud_platform) shall not contain '_' according to RFC3986.
[2024-03-15T01:59:12.200+0000] {base.py:83} INFO - Using connection ID 'gcp_***_conn' for task execution.
[2024-03-15T01:59:12.327+0000] {taskinstance.py:2731} ERROR - Task failed with exception
Traceback (most recent call last):
  File "/home/airflow/.local/lib/python3.8/site-packages/airflow/models/taskinstance.py", line 444, in _execute_task
    result = _execute_callable(context=context, **execute_callable_kwargs)
  File "/home/airflow/.local/lib/python3.8/site-packages/airflow/models/taskinstance.py", line 414, in _execute_callable
    return execute_callable(context=context, **execute_callable_kwargs)
  File "/home/airflow/.local/lib/python3.8/site-packages/airflow/providers/google/cloud/transfers/local_to_gcs.py", line 97, in execute
    raise FileNotFoundError(self.src)
FileNotFoundError: /home/hariatde_gmail_com/project-used-cars/Used-Car-Price-data-analysiss/data/raw/car_sales.csv.gz
[2024-03-15T01:59:12.339+0000] {taskinstance.py:1149} INFO - Marking task as FAILED. dag_id=source_to_gcs, task_id=upload_file_gcs, execution_date=20240315T015759, start_date=20240315T015911, end_date=20240315T015912
[2024-03-15T01:59:12.357+0000] {standard_task_runner.py:107} ERROR - Failed to execute job 13 for task upload_file_gcs (/home/hariatde_gmail_com/project-used-cars/Used-Car-Price-data-analysiss/data/raw/car_sales.csv.gz; 349)
[2024-03-15T01:59:12.388+0000] {local_task_job_runner.py:234} INFO - Task exited with return code 1
[2024-03-15T01:59:12.413+0000] {taskinstance.py:3312} INFO - 0 downstream tasks scheduled from follow-on schedule check
