[2024-03-23T07:28:32.465+0000] {taskinstance.py:1979} INFO - Dependencies all met for dep_context=non-requeueable deps ti=<TaskInstance: check_errors.check_value_for manual__2024-03-23T07:20:28.195572+00:00 [queued]>
[2024-03-23T07:28:32.478+0000] {taskinstance.py:1979} INFO - Dependencies all met for dep_context=requeueable deps ti=<TaskInstance: check_errors.check_value_for manual__2024-03-23T07:20:28.195572+00:00 [queued]>
[2024-03-23T07:28:32.478+0000] {taskinstance.py:2193} INFO - Starting attempt 3 of 3
[2024-03-23T07:28:32.498+0000] {taskinstance.py:2217} INFO - Executing <Task(PythonOperator): check_value_for> on 2024-03-23 07:20:28.195572+00:00
[2024-03-23T07:28:32.510+0000] {standard_task_runner.py:60} INFO - Started process 1732 to run task
[2024-03-23T07:28:32.518+0000] {standard_task_runner.py:87} INFO - Running: ['***', 'tasks', 'run', 'check_errors', 'check_value_for', 'manual__2024-03-23T07:20:28.195572+00:00', '--job-id', '241', '--raw', '--subdir', 'DAGS_FOLDER/check_erros.py', '--cfg-path', '/tmp/tmptfspc2g3']
[2024-03-23T07:28:32.523+0000] {standard_task_runner.py:88} INFO - Job 241: Subtask check_value_for
[2024-03-23T07:28:32.606+0000] {task_command.py:423} INFO - Running <TaskInstance: check_errors.check_value_for manual__2024-03-23T07:20:28.195572+00:00 [running]> on host ceb99a37e23c
[2024-03-23T07:28:32.747+0000] {taskinstance.py:2513} INFO - Exporting env vars: AIRFLOW_CTX_DAG_OWNER='***' AIRFLOW_CTX_DAG_ID='check_errors' AIRFLOW_CTX_TASK_ID='check_value_for' AIRFLOW_CTX_EXECUTION_DATE='2024-03-23T07:20:28.195572+00:00' AIRFLOW_CTX_TRY_NUMBER='3' AIRFLOW_CTX_DAG_RUN_ID='manual__2024-03-23T07:20:28.195572+00:00'
[2024-03-23T07:28:32.753+0000] {taskinstance.py:2731} ERROR - Task failed with exception
Traceback (most recent call last):
  File "/home/airflow/.local/lib/python3.8/site-packages/airflow/models/taskinstance.py", line 444, in _execute_task
    result = _execute_callable(context=context, **execute_callable_kwargs)
  File "/home/airflow/.local/lib/python3.8/site-packages/airflow/models/taskinstance.py", line 414, in _execute_callable
    return execute_callable(context=context, **execute_callable_kwargs)
  File "/home/airflow/.local/lib/python3.8/site-packages/airflow/operators/python.py", line 200, in execute
    return_value = self.execute_callable()
  File "/home/airflow/.local/lib/python3.8/site-packages/airflow/operators/python.py", line 217, in execute_callable
    return self.python_callable(*self.op_args, **self.op_kwargs)
  File "/opt/airflow/dags/check_erros.py", line 36, in check_values
    check_value = BigQueryCheckOperator(
TypeError: execute() missing 1 required positional argument: 'context'
[2024-03-23T07:28:32.771+0000] {taskinstance.py:1149} INFO - Marking task as FAILED. dag_id=check_errors, task_id=check_value_for, execution_date=20240323T072028, start_date=20240323T072832, end_date=20240323T072832
[2024-03-23T07:28:32.790+0000] {standard_task_runner.py:107} ERROR - Failed to execute job 241 for task check_value_for (execute() missing 1 required positional argument: 'context'; 1732)
[2024-03-23T07:28:32.823+0000] {local_task_job_runner.py:234} INFO - Task exited with return code 1
[2024-03-23T07:28:32.853+0000] {taskinstance.py:3312} INFO - 0 downstream tasks scheduled from follow-on schedule check
